Traceback (most recent call last):
  File "/scratch/tln229/Code_core/ML_Changepoint_Detection_epigenomic_rnn/model/gru/run_one.py", line 24, in <module>
    params = params_df.iloc[param_row]
             ~~~~~~~~~~~~~~^^^^^^^^^^^
  File "/home/tln229/.conda/envs/myenv/lib/python3.11/site-packages/pandas/core/indexing.py", line 1191, in __getitem__
    return self._getitem_axis(maybe_callable, axis=axis)
           ^^^^^^^^^^^^^^^^^^^^^^^^^^^^^^^^^^^^^^^^^^^^^
  File "/home/tln229/.conda/envs/myenv/lib/python3.11/site-packages/pandas/core/indexing.py", line 1752, in _getitem_axis
    self._validate_integer(key, axis)
  File "/home/tln229/.conda/envs/myenv/lib/python3.11/site-packages/pandas/core/indexing.py", line 1685, in _validate_integer
    raise IndexError("single positional indexer is out-of-bounds")
IndexError: single positional indexer is out-of-bounds
